Workbook

Sheet Comparaciones
B1: Modelo | C1: promedio
B2: qwen25_3b | C2: =AVERAGE(qwen25_3b!C2:C51) -> 0.38
B3: gemma_7b | C3: =AVERAGE(gemma_7b!C2:C51) -> 0.502
B4: mistral_7b | C4: =AVERAGE(mistral_7b!C2:C51) -> 0.486
B5: deepseek_R1_8b | C5: =AVERAGE(deepseek_R1_8b!C2:C51) -> 0.766
B6: llama31_8b | C6: =AVERAGE(llama31_8b!C2:C51) -> 0.6
B7: llama33_70b | C7: =AVERAGE(llama33_70b!C2:C51) -> 0.872
B8: mistral_devstral2_123b | C8: =AVERAGE(Mistral_devstral2_123b!C2:C51) -> 0.89
B9: xiaomi_mimoV2_flash_15b_309b | C9: =AVERAGE(Xiaomi_mimoV2_flash_15b_309b!C2:C51) -> 0.902
B10: qwen3_coder_35b_480b | C10: =AVERAGE(qwen3_coder_35b_480b!C2:C51) -> 0.852
B11: deepseek_r1t2_chimera_671b | C11: =AVERAGE(deepseek_r1t2_chimera_671b!C2:C51) -> 0.912
B15: pregunta | C15: promedio
B16: 1 | C16: =AVERAGE(qwen25_3b!C2,gemma_7b!C2,llama31_8b!C2,mistral_7b!C2,llama33_70b!C2,qwen3_coder_35b_480b!C2,deepseek_r1t2_chimera_671b!C2,deepseek_R1_8b!C2,Xiaomi_mimoV2_flash_15b_309b!C2,Mistral_devstral2_123b!C2) -> 0.91
B17: 2 | C17: =AVERAGE(qwen25_3b!C3,gemma_7b!C3,llama31_8b!C3,mistral_7b!C3,llama33_70b!C3,qwen3_coder_35b_480b!C3,deepseek_r1t2_chimera_671b!C3,deepseek_R1_8b!C3,Xiaomi_mimoV2_flash_15b_309b!C3,Mistral_devstral2_123b!C3) -> 0.92
B18: 3 | C18: =AVERAGE(qwen25_3b!C4,gemma_7b!C4,llama31_8b!C4,mistral_7b!C4,llama33_70b!C4,qwen3_coder_35b_480b!C4,deepseek_r1t2_chimera_671b!C4,deepseek_R1_8b!C4,Xiaomi_mimoV2_flash_15b_309b!C4,Mistral_devstral2_123b!C4) -> 0.91
B19: 4 | C19: =AVERAGE(qwen25_3b!C5,gemma_7b!C5,llama31_8b!C5,mistral_7b!C5,llama33_70b!C5,qwen3_coder_35b_480b!C5,deepseek_r1t2_chimera_671b!C5,deepseek_R1_8b!C5,Xiaomi_mimoV2_flash_15b_309b!C5,Mistral_devstral2_123b!C5) -> 0.93
B20: 5 | C20: =AVERAGE(qwen25_3b!C6,gemma_7b!C6,llama31_8b!C6,mistral_7b!C6,llama33_70b!C6,qwen3_coder_35b_480b!C6,deepseek_r1t2_chimera_671b!C6,deepseek_R1_8b!C6,Xiaomi_mimoV2_flash_15b_309b!C6,Mistral_devstral2_123b!C6) -> 0.98
B21: 6 | C21: =AVERAGE(qwen25_3b!C7,gemma_7b!C7,llama31_8b!C7,mistral_7b!C7,llama33_70b!C7,qwen3_coder_35b_480b!C7,deepseek_r1t2_chimera_671b!C7,deepseek_R1_8b!C7,Xiaomi_mimoV2_flash_15b_309b!C7,Mistral_devstral2_123b!C7) -> 0.78
B22: 7 | C22: =AVERAGE(qwen25_3b!C8,gemma_7b!C8,llama31_8b!C8,mistral_7b!C8,llama33_70b!C8,qwen3_coder_35b_480b!C8,deepseek_r1t2_chimera_671b!C8,deepseek_R1_8b!C8,Xiaomi_mimoV2_flash_15b_309b!C8,Mistral_devstral2_123b!C8) -> 0.77
B23: 8 | C23: =AVERAGE(qwen25_3b!C9,gemma_7b!C9,llama31_8b!C9,mistral_7b!C9,llama33_70b!C9,qwen3_coder_35b_480b!C9,deepseek_r1t2_chimera_671b!C9,deepseek_R1_8b!C9,Xiaomi_mimoV2_flash_15b_309b!C9,Mistral_devstral2_123b!C9) -> 0.79
B24: 9 | C24: =AVERAGE(qwen25_3b!C10,gemma_7b!C10,llama31_8b!C10,mistral_7b!C10,llama33_70b!C10,qwen3_coder_35b_480b!C10,deepseek_r1t2_chimera_671b!C10,deepseek_R1_8b!C10,Xiaomi_mimoV2_flash_15b_309b!C10,Mistral_devstral2_123b!C10) -> 0.88
B25: 10 | C25: =AVERAGE(qwen25_3b!C11,gemma_7b!C11,llama31_8b!C11,mistral_7b!C11,llama33_70b!C11,qwen3_coder_35b_480b!C11,deepseek_r1t2_chimera_671b!C11,deepseek_R1_8b!C11,Xiaomi_mimoV2_flash_15b_309b!C11,Mistral_devstral2_123b!C11) -> 0.6
B26: 11 | C26: =AVERAGE(qwen25_3b!C12,gemma_7b!C12,llama31_8b!C12,mistral_7b!C12,llama33_70b!C12,qwen3_coder_35b_480b!C12,deepseek_r1t2_chimera_671b!C12,deepseek_R1_8b!C12,Xiaomi_mimoV2_flash_15b_309b!C12,Mistral_devstral2_123b!C12) -> 0.76
B27: 12 | C27: =AVERAGE(qwen25_3b!C13,gemma_7b!C13,llama31_8b!C13,mistral_7b!C13,llama33_70b!C13,qwen3_coder_35b_480b!C13,deepseek_r1t2_chimera_671b!C13,deepseek_R1_8b!C13,Xiaomi_mimoV2_flash_15b_309b!C13,Mistral_devstral2_123b!C13) -> 0.64
... B65: 50 | C65: =AVERAGE(qwen25_3b!C51,gemma_7b!C51,llama31_8b!C51,mistral_7b!C51,llama33_70b!C51,qwen3_coder_35b_480b!C51,deepseek_r1t2_chimera_671b!C51,deepseek_R1_8b!C51,Xiaomi_mimoV2_flash_15b_309b!C51,Mistral_devstral2_123b!C51) -> 0.59

Sheet Orden_preguntas
A1: ID_PREGUNTA | B1: Pregunta
A2: 1 | B2: ¿Cuánto consumió mi televisor ayer en la noche?
A3: 2 | B3: Dime el consumo de mi lavadora el lunes pasado.
A4: 3 | B4: ¿Cuál fue el consumo total de la casa durante marzo de 2024?
A5: 4 | B5: Quiero saber cuánta energía gastó mi computador hoy.
A6: 5 | B6: ¿Cuánto consumió el aire acondicionado el fin de semana pasado?
A7: 6 | B7: Muéstrame el consumo del ventilador el día de ayer.
A8: 7 | B8: ¿Cuál fue el consumo energético de mi horno el 15 de noviembre?
A9: 8 | B9: Dime cuántos kWh consumió mi casa la semana pasada.
A10: 9 | B10: ¿Cuánto consumió mi nevera durante el mes de enero?
A11: 10 | B11: ¿Qué tan feliz estuvo mi casa ayer con el consumo de energía?
A12: 11 | B12: Dime el consumo de mi nevera ayer y el consumo de mi lavadora ayer.
A13: 12 | B13: ¿Cuánto consumieron el televisor y el computador el sábado pasado?
... A51: 50 | B51: Dime el consumo de mi nevera ayer, compárala con la lavadora y dime si con eso ya puedo ahorrar para irme de viaje.

Sheet qwen25_3b
A1: ID_PREGUNTA | B1: Respuesta_Modelo | C1: Puntaje_Calidad | D1: Razon_del_Juez | E1: Pregunta
A2: =_xlfn.XLOOKUP(E2,Orden_preguntas!$B:$B,Orden_preguntas!$A:$A) -> 1 | B2: {'@1': {'solicitud': '¿Cuánto consumió mi televisor ayer en la noche?', 'escenario': 'consumo_basico'}} | notas: La solicitud especifica el consumo de un dispositivo (televisor) durante un intervalo de tiempo específico (ayer en la noche), lo que corresponde con el escenario 'consumo_basico'. [[## completed ##]] | C2: 1 | D2: The model correctly decomposes the input into a single intention (A1) without inventing information (A2), using the exact input text for the 'solicitud' field. The assigned scenario classification 'consumo_basico' is correct and aligns with the Expected Output (B1). Implicit intentions are correctly inferred as the request is direct (A3). The 'notas' field provides clear and consistent reasoning for the classification, demonstrating strong internal coherence (A4). All criteria for the 8-10 range are met. | E2: ¿Cuánto consumió mi televisor ayer en la noche?
A3: =_xlfn.XLOOKUP(E3,Orden_preguntas!$B:$B,Orden_preguntas!$A:$A) -> 2 | B3: {'1': {'solicitud': 'Dime el consumo de mi lavadora el lunes pasado.', 'escenario': '@consumo_basico'}} | notas: La solicitud pide una consulta histórica específica, que es un ejemplo claramente de la intención principal del escenario 'consumo_basico'. [[## completed ##]] | C3: 1 | D3: The model correctly decomposes the input into a single request, accurately reflecting the user's intention without inventing any information (A1, A2). The interpretation of the request, 'Dime el consumo de mi lavadora el lunes pasado.', aligns perfectly with the expected output's intention to 'Consultar el consumo energético de la lavadora el lunes pasado.' (A3). Furthermore, the model correctly assigns the request to the '@consumo_basico' scenario, which matches the 'consumo_basico' scenario in the expected output (B1). The 'notas' field provides a clear and coherent explanation for this classification (A4). | E3: Dime el consumo de mi lavadora el lunes pasado.
A4: =_xlfn.XLOOKUP(E4,Orden_preguntas!$B:$B,Orden_preguntas!$A:$A) -> 3 | B4: {'1': {'solicitud': '¿Cuál fue el consumo total de la casa durante marzo de 2024?', 'escenario': 'consumo_basico'}} | notas: La solicitud expresa una consulta de valores históricos específicos del consumo energético para un período temporal (marzo de 2024), por lo que se considera el escenario 'consumo_basico'. [[## completed ##]] | C4: 1 | D4: The model correctly decomposes the input into a single intention, which is '¿Cuál fue el consumo total de la casa durante marzo de 2024?'. It accurately classifies this request under the 'consumo_basico' scenario, aligning perfectly with the Expected Output. Furthermore, the 'notas' field provides a clear and consistent explanation for this classification, referencing the historical and temporal nature of the consumption query for March 2024. All criteria (A1-A4 and B1) are met without inventing information or showing incoherence. | E4: ¿Cuál fue el consumo total de la casa durante marzo de 2024?
A5: =_xlfn.XLOOKUP(E5,Orden_preguntas!$B:$B,Orden_preguntas!$A:$A) -> 4 | B5: {'1': {'solicitud': 'Quiero saber cuánta energía gastó mi computador hoy.', 'escenario': 'consumo_basico'}} | notas: La solicitud implica un período de tiempo explícito (hoy) y una consulta para obtener datos puntuales sobre el consumo del dispositivo, por lo que se categoriza como 'consumo_basico'. [[## completed ##]] | C5: 0.9 | D5: The model correctly decomposes the input into a single intention (A1) without inventing information (A2). The assigned scenario classification 'consumo_basico' is correct and aligns with the Expected Output (B1). The 'notas' field provides clear and consistent reasoning for the classification, demonstrating internal coherence (A4). While the 'solicitud' in the Actual Output is a direct copy of the input rather than a rephrased version like in the Expected Output, it accurately captures the user's intent and does not constitute an error according to the rubric. | E5: Quiero saber cuánta energía gastó mi computador hoy.
A6: =_xlfn.XLOOKUP(E6,Orden_preguntas!$B:$B,Orden_preguntas!$A:$A) -> 5 | B6: {'@1': {'solicitud': '¿Cuánto consumió el aire acondicionado el fin de semana pasado?', 'escenario': 'consumo_basico'}} | notas: La solicitud implica la consulta de una cantidad específica de energía consumida por un dispositivo específico (aire acondicionado) dentro de un período temporal especificado (fin de semana), sin realizar comparaciones, análisis de patrones ni estimaciones. Se ajusta al escenario "consumo_basico". | C6: 1 | D6: The model correctly decomposes the input into a single, independent intention (A1) without inventing information (A2). It accurately classifies the intention as 'consumo_basico' (B1), aligning with the Expected Output. Furthermore, the 'notas' field provides a clear and coherent explanation for this classification, referencing the specific device (aire acondicionado) and time period (fin de semana) from the input, demonstrating strong internal coherence (A4). | E6: ¿Cuánto consumió el aire acondicionado el fin de semana pasado?
A7: =_xlfn.XLOOKUP(E7,Orden_preguntas!$B:$B,Orden_preguntas!$A:$A) -> 6 | B7: {'@1': {'solicitud': 'Muéstrame el consumo del ventilador el día de ayer.', 'escenario': 'consumo_basico'}} | notas: La solicitud menciona un dispositivo (ventilador) y un período de tiempo (el día de ayer), lo que clasifica esta consulta en el escenario 'consumo_basico'. La respuesta esperada es un valor cuantitativo único, ya que se está pidiendo información histórica sobre el consumo específico del ventilador. | C7: 1 | D7: The model correctly decomposes the input 'Muéstrame el consumo del ventilador el día de ayer' into a single intention, aligning with the Expected Output. It accurately classifies this intention under the 'consumo_basico' scenario, which matches the Expected Output's classification. Furthermore, the 'notas' field provides a clear and consistent explanation for this classification, demonstrating strong internal coherence. No information is invented, and all evaluation criteria (A1-A4, B1) are fully met. | E7: Muéstrame el consumo del ventilador el día de ayer.
A8: =_xlfn.XLOOKUP(E8,Orden_preguntas!$B:$B,Orden_preguntas!$A:$A) -> 7 | B8: {'@1': {'solicitud': '¿Cuál fue el consumo energético de mi horno el 15 de noviembre?', 'escenario': 'consumo_basico'}} | notas: La solicitud menciona un dispositivo específico (horno) y una fecha específica para un valor cuantitativo histórico, que son características típicas del escenario 'consumo_basico'. | C8: 1 | D8: The model correctly decomposes the input into a single intention, which aligns with the expected output (A1). It does not invent any information (A2). The scenario classification 'consumo_basico' is accurate and matches the expected output (B1). The 'notas' field provides clear and consistent reasoning for the classification, demonstrating strong internal coherence (A4). No implicit intentions needed to be inferred beyond what was explicitly asked (A3). | E8: ¿Cuál fue el consumo energético de mi horno el 15 de noviembre?
A9: =_xlfn.XLOOKUP(E9,Orden_preguntas!$B:$B,Orden_preguntas!$A:$A) -> 8 | B9: {'@1': {'solicitud': 'Dime cuántos kWh consumió mi casa la semana pasada.', 'escenario': 'consumo_basico'}} | notas: La solicitud pide valores de consumo energético históricos para un período de tiempo específico (la semana pasada), por lo que se ajusta al escenario 'consumo_basico'. [[## completed ##]] | C9: 0.9 | D9: The model correctly decomposes the input into a single request and does not invent any information (A1, A2). It accurately identifies the user's intention to query historical energy consumption for a specific period ('la semana pasada'), aligning with the expected interpretation (A3). The assigned scenario 'consumo_basico' is correct and consistent with the request and the expected output (B1). The 'notas' field provides a clear and coherent justification for the scenario assignment (A4). The only minor deviation from the Expected Output is that the 'solicitud' field is a direct copy of the input rather than a rephrased, more abstract intention, but this does not constitute an error in interpretation or decomposition. | E9: Dime cuántos kWh consumió mi casa la semana pasada.
A10: =_xlfn.XLOOKUP(E10,Orden_preguntas!$B:$B,Orden_preguntas!$A:$A) -> 9 | B10: {'@1': {'solicitud': '¿Cuánto consumió mi nevera durante el mes de enero?', 'escenario': 'consumo_basico'}} | notas: La solicitud busca conocer los valores históricos del consumo de la nevera, dentro de un intervalo temporal (el mes de enero), y la respuesta esperada es un valor cuantitativo único. Entonces se identifica el escenario 'consumo_basico'. [[## completed ##]] | C10: 1 | D10: The model correctly decomposes the input into a single intention (A1) without inventing information (A2). The assigned scenario classification 'consumo_basico' is correct and aligns with the Expected Output (B1). The reasoning provided in the 'notas' field is clear, consistent, and accurately justifies the classification, demonstrating strong internal coherence (A4). No complex implicit intentions were present, but the model handled the direct query effectively (A3). | E10: ¿Cuánto consumió mi nevera durante el mes de enero?
A11: =_xlfn.XLOOKUP(E11,Orden_preguntas!$B:$B,Orden_preguntas!$A:$A) -> 10 | B11: {'@1': {'solicitud': '¿Qué tan feliz estuvo mi casa ayer con el consumo de energía?', 'escenario': 'entrada_inadmisible'}} | notas: La solicitud no está relacionada con consumo energético, ya que se pregunta sobre la felicidad del hogar en relación con su consumo de energía. Es una consulta ambigua y carece de contexto. [[## completed ##]] | C11: 1 | D11: The model correctly decomposed the input into a single intention without inventing information. It accurately classified the request '¿Qué tan feliz estuvo mi casa ayer con el consumo de energía?' as 'entrada_inadmisible', which is correct given its non-technical nature. The reasoning provided in the 'notas' field is clear, consistent, and fully supports the assigned classification. | E11: ¿Qué tan feliz estuvo mi casa ayer con el consumo de energía?
A12: =_xlfn.XLOOKUP(E12,Orden_preguntas!$B:$B,Orden_preguntas!$A:$A) -> 11 | B12: {'@1': {'solicitud': 'El consumo de mi nevera ayer y el consumo de mi lavadora ayer.', 'escenario': 'consumo_basico'}} | notas: La solicitud implica la comparación entre dos consumos energéticos (nevera y lavadora) para un mismo día, lo que se ajusta al escenario 'comparacion_consumos'. [[## completed ##]] | C12: 0.2 | D12: The model fails to correctly decompose the input into individual, independent intentions, combining two distinct requests for 'nevera' and 'lavadora' consumption into a single entry, which is a failure in A1. It also exhibits a significant internal inconsistency (A4) where the assigned 'escenario' of 'consumo_basico' directly contradicts the reasoning provided in the 'notas' field, which states the request 'se ajusta al escenario 'comparacion_consumos''. This demonstrates a fundamental misunderstanding of the request's structure and classification. | E12: Dime el consumo de mi nevera ayer y el consumo de mi lavadora ayer.
A13: =_xlfn.XLOOKUP(E13,Orden_preguntas!$B:$B,Orden_preguntas!$A:$A) -> 12 | B13: {'@1': {'solicitud': '¿Cuánto consumieron el televisor y el computador el sábado pasado?', 'escenario': 'consumo_basico'}} | notas: La solicitud menciona específicamente valores de consumo para dos dispositivos distintos, solicitando información histórica sobre un intervalo temporal definido (el sábado pasado). Esto corresponde a la intención admitida en el escenario de 'consumo_basico'. [[## completed ##]] | C13: 0.3 | D13: The model fails to correctly decompose the input into all individual, independent intentions (A1). The input asks about 'el televisor y el computador', which should be decomposed into two distinct requests, one for each device, as shown in the Expected Output. Instead, the Actual Output combines them into a single request. This also indicates a failure to adequately infer implicit intentions (A3). While the scenario classification for the single identified request is correct (B1) and the 'notas' field is internally coherent for that single request (A4), the fundamental failure in decomposition places it in the lower score range. | E13: ¿Cuánto consumieron el televisor y el computador el sábado pasado?
... A51: =_xlfn.XLOOKUP(E51,Orden_preguntas!$B:$B,Orden_preguntas!$A:$A) -> 50 | B51: {'@1': {'solicitud': 'Dime el consumo de mi nevera ayer, compárala con la lavadora y dime si con eso ya puedo ahorrar para irme de viaje.', 'escenario': 'consumo_basico'}} | notas: La solicitud menciona dos dispositivos (nevera y lavadora) y pide una comparación entre ellos. Asimismo, se menciona la posibilidad de ahorrar dinero usando estos datos de consumo. Este escenario coincide con el 'comparacion_consumos'. [[## completed ##]] | C51: 0.1 | D51: The model failed significantly in decomposing the input into individual, independent intentions (A1), treating the entire complex request as a single intention instead of three distinct ones as shown in the Expected Output. Additionally, there is a clear internal incoherence (A4) as the 'notas' field explicitly states that the scenario coincides with 'comparacion_consumos', while the assigned 'escenario' for the request is 'consumo_basico'. The classification (B1) for the combined intention is also incorrect. | E51: Dime el consumo de mi nevera ayer, compárala con la lavadora y dime si con eso ya puedo ahorrar para irme de viaje.

Sheet gemma_7b
A1: ID_PREGUNTA | B1: Respuesta_Modelo | C1: Puntaje_Calidad | D1: Razon_del_Juez | E1: Pregunta
A2: =_xlfn.XLOOKUP(E2,Orden_preguntas!$B:$B,Orden_preguntas!$A:$A) -> 1 | B2: {'1': {'solicitud': '¿Cuánto consumió mi televisor ayer en la noche?', 'escenario': 'consumo_basico'}, '2': {'solicitud': 'Consulta de consumo energético histórico del televisor.', 'escenario': 'consumo_basico'}} | notas: La solicitud se ajusta a los criterios de 'consumo_basico', que se refiere a solicitudes para consultar valores de consumo energético ya registrados para un dispositivo o periodo de tiempo específico. | C2: 0.4 | D2: The model incorrectly decomposes the single input request into two separate requests, where the second request ('Consulta de consumo energético histórico del televisor.') is redundant and not an independent action (A1). This also leads to a less precise interpretation compared to the Expected Output's single, specific request (A3). While the assigned scenario 'consumo_basico' is correct for the nature of the query (B1), the flawed decomposition and the slight incoherence in the 'notas' field (referring to 'La solicitud' in singular despite two requests) indicate insufficient semantic quality (A1-A4). | E2: ¿Cuánto consumió mi televisor ayer en la noche?
A3: =_xlfn.XLOOKUP(E3,Orden_preguntas!$B:$B,Orden_preguntas!$A:$A) -> 2 | B3: {'1': {'solicitud': 'Obtener consumo de la lavadora el lunes pasado', 'escenario': 'consumo_basico'}, '2': {'solicitud': 'Consulta de datos puntuales', 'escenario': 'consumo_basico'}} | notas: La solicitud es una consulta de consumo puntual de energía para un dispositivo específico (lavadora) en un período específico (lunes pasado). | C3: 0.3 | D3: The model incorrectly decomposes the single user request 'Dime el consumo de mi lavadora el lunes pasado' into two separate requests. The second request, 'Consulta de datos puntuales', is redundant and not an independent intention, indicating a failure in correctly decomposing the input into individual, independent requests (A1) and a misinterpretation of the input's natural language structure (A3). While the primary intention and scenario ('consumo_basico') are correctly identified, the flawed decomposition significantly impacts the semantic quality. | E3: Dime el consumo de mi lavadora el lunes pasado.
A4: =_xlfn.XLOOKUP(E4,Orden_preguntas!$B:$B,Orden_preguntas!$A:$A) -> 3 | B4: {'1': {'solicitud': 'Calcular el consumo total de la casa durante marzo de 2024.', 'escenario': 'consumo_basico'}, '2': {'solicitud': 'Obtener valores puntuales de consumo energético para marzo de 2024.', 'escenario': 'consumo_basico'}} | notas: La solicitud se ajusta al escenario de consumo básico, que se define como la consulta de valores de consumo energético ya registrados para un período específico. | C4: 0.3 | D4: The model fails in decomposing the input request, creating two intentions where only one is present in the input. Specifically, the input asks for 'consumo total', which is a single aggregated value, but the actual output includes a second intention to 'Obtener valores puntuales de consumo energético', which is an over-decomposition and misinterpretation of the original request. This indicates a failure in criteria A1 (decomposition) and potentially A2 (inventing information), aligning with the 0-4 score range. | E4: ¿Cuál fue el consumo total de la casa durante marzo de 2024?
A5: =_xlfn.XLOOKUP(E5,Orden_preguntas!$B:$B,Orden_preguntas!$A:$A) -> 4 | B5: {'1': {'solicitud': '¿Cuanto energía ha consumido mi computador hoy?', 'escenario': 'consumo_basico'}, '2': {'solicitud': 'Consulta de consumo puntual de energía de un dispositivo específico', 'escenario': 'consumo_basico'}} | notas: La solicitud es una consulta de consumo energético puntual de un dispositivo específico. Se ajusta al escenario de entrada "consumo_basico". | C5: 0.4 | D5: The model fails in the decomposition of the input request (A1). It incorrectly breaks down the single, straightforward input 'Quiero saber cuánta energía gastó mi computador hoy' into two requests, where the second request ('Consulta de consumo puntual de energía de un dispositivo específico') is redundant and acts more as a description of the first request rather than an independent intention. This also leads to a misalignment with the Expected Output's single, concise request (A3). While the identified scenario 'consumo_basico' is correct (B1) and no information is invented (A2), the flawed decomposition and structural inconsistency with the expected output indicate insufficient semantic quality (A1-A4). | E5: Quiero saber cuánta energía gastó mi computador hoy.
A6: =_xlfn.XLOOKUP(E6,Orden_preguntas!$B:$B,Orden_preguntas!$A:$A) -> 5 | B6: {'@1': {'solicitud': '¿Cuánto consumió el aire acondicionado el fin de semana pasado?', 'escenario': 'consumo_basico'}} | notas: La solicitud se ajusta al escenario de consumo básico, que se refiere a solicitudes para obtener valores de consumo energético históricos de dispositivos o zonas del hogar. | C6: 1 | D6: The model correctly decomposes the input into a single request (A1) and does not invent any information (A2). The inferred intention of consulting energy consumption for the air conditioner last weekend aligns perfectly with the `Expected Output`'s interpretation, even though the `solicitud` field is a direct copy of the input rather than a rephrasing (A3). The `notas` field is clear and coherent, accurately describing the request (A4). Finally, the request is correctly classified into the 'consumo_basico' scenario, matching the `Expected Output` (B1). | E6: ¿Cuánto consumió el aire acondicionado el fin de semana pasado?
A7: =_xlfn.XLOOKUP(E7,Orden_preguntas!$B:$B,Orden_preguntas!$A:$A) -> 6 | B7: {'1': {'solicitud': 'Muéstreme el consumo del ventilador el día de ayer.', 'escenario': 'consumo_basico'}, '2': {'solicitud': 'Muestre consumo del ventilador en el día ayer.', 'escenario': 'entrada_inadmisible'}} | notas: La solicitud es clara y se ajusta al escenario de consumo básico, que se refiere a consultas de valores de consumo energético históricos o puntuales. Sin embargo, la solicitud específica de consumo de un ventilador solo para el día de ayer no es compatible con el escenario de entrada admitido. | C7: 0.2 | D7: The model fails significantly in decomposing the input, incorrectly splitting a single, clear intention into two. It invents a second, redundant intention ('Muestre consumo del ventilador en el día ayer.') and then classifies it as 'entrada_inadmisible', which contradicts its classification of the first intention ('consumo_basico') and the overall validity of the input. Furthermore, the 'notas' field exhibits a clear lack of internal coherence, stating that the request 'se ajusta al escenario de consumo básico' but then immediately contradicting itself by saying it 'no es compatible con el escenario de entrada admitido'. This demonstrates a fundamental misunderstanding of the input and its own classification logic, failing criteria A1, A2, and A4. | E7: Muéstrame el consumo del ventilador el día de ayer.
A8: =_xlfn.XLOOKUP(E8,Orden_preguntas!$B:$B,Orden_preguntas!$A:$A) -> 7 | B8: {'1': {'solicitud': 'Consulta del consumo energético histórico del horno en el 15 de noviembre', 'escenario': 'consumo_basico'}, '2': {'solicitud': 'Proporcionar detalles sobre el consumo energético del horno en el 15 de noviembre', 'escenario': 'prediccion_estimacion'}} | notas: La solicitud especifica la búsqueda de datos históricos relacionados con el consumo energético del horno en una fecha específica. Este tipo de consulta se ajusta a los escenarios de entrada 'consumo_basico' y 'prediccion_estimacion'. | C8: 0.3 | D8: The model fails to correctly decompose the input, identifying two requests when the input '¿Cuál fue el consumo energético de mi horno el 15 de noviembre?' clearly represents a single, historical query. The second decomposed request, 'Proporcionar detalles sobre el consumo energético del horno en el 15 de noviembre', is redundant and not an independent intention (A1). Furthermore, this second request is incorrectly classified under the 'prediccion_estimacion' scenario, which contradicts the historical nature of the input (B1). The 'notas' field also exhibits incoherence by justifying both 'consumo_basico' and 'prediccion_estimacion' for a historical data request (A4). | E8: ¿Cuál fue el consumo energético de mi horno el 15 de noviembre?
A9: =_xlfn.XLOOKUP(E9,Orden_preguntas!$B:$B,Orden_preguntas!$A:$A) -> 8 | B9: {'1': {'solicitud': 'Obtener valores de consumo energético históricos de la casa', 'escenario': 'consumo_basico'}, '2': {'solicitud': 'Mostrar consumo energético por semana', 'escenario': 'consumo_basico'}} | notas: La solicitud se refiere a datos históricos de consumo energético de la casa y a un consumo específico por semana. | C9: 0.3 | D9: The model fails in the decomposition of the request (A1). The input 'Dime cuántos kWh consumió mi casa la semana pasada' represents a single, specific intention, as correctly identified by the Expected Output. However, the Actual Output incorrectly decomposes this into two separate intentions: 'Obtener valores de consumo energético históricos de la casa' and 'Mostrar consumo energético por semana'. This over-decomposition and misidentification of individual, independent intentions is a significant shortcoming. While the scenario classification 'consumo_basico' is correct for both identified intentions (B1) and the 'notas' field is internally consistent with the Actual Output's decomposition (A4), the fundamental failure in A1 places the score in the lower range of the rubric. | E9: Dime cuántos kWh consumió mi casa la semana pasada.
A10: =_xlfn.XLOOKUP(E10,Orden_preguntas!$B:$B,Orden_preguntas!$A:$A) -> 9 | B10: {'1': {'solicitud': '¿Cuánto consumió mi nevera durante el mes de enero?', 'escenario': 'consumo_basico'}, '2': {'solicitud': 'Calcular el consumo mensual de la nevera.', 'escenario': 'prediccion_estimacion'}} | notas: La solicitud es clara y se ajusta a los escenarios de entrada 'consumo_basico' y 'prediccion_estimacion'. Se requiere acceder a datos históricos de consumo energético de la nevera para calcular el consumo mensual. | C10: 0.3 | D10: The model correctly identifies and classifies the primary intention '¿Cuánto consumió mi nevera durante el mes de enero?' as 'consumo_basico', aligning with the Expected Output. However, it incorrectly decomposes the input by inventing a second, independent intention: 'Calcular el consumo mensual de la nevera'. This is not an explicit or implicit user request but rather an internal system operation. Furthermore, this invented intention is incorrectly classified as 'prediccion_estimacion', which contradicts the input's request for historical data. This demonstrates a failure in correctly decomposing the input (A1), inventing information not present (A2), and incorrect scenario classification (B1) for the second intention, placing it in the 0-4 range of the rubric. | E10: ¿Cuánto consumió mi nevera durante el mes de enero?
A11: =_xlfn.XLOOKUP(E11,Orden_preguntas!$B:$B,Orden_preguntas!$A:$A) -> 10 | B11: {'1': {'solicitud': '¿Qué tan feliz estuvo mi casa ayer con el consumo de energía?', 'escenario': 'entrada_inadmisible'}, '2': {'solicitud': 'Calcular la felicidad del hogar ayer en función del consumo energético', 'escenario': 'prediccion_estimacion'}} | notas: La solicitud es ambigua. No es posible determinar directamente la felicidad de la casa en función del consumo energético. Sin embargo, es posible estimar el consumo energético pasado y evaluar su impacto en la felicidad general de la casa. | C11: 0.3 | D11: The model incorrectly decomposes the input by creating a second, reinterpreted request ('Calcular la felicidad del hogar ayer en función del consumo energético') that is not an independent intention deducible from the original input (A1, A2). This second request attempts to invent an actionable interpretation for a non-technical query, diverging from the Expected Output's interpretation that the entire intention is inadmissible (A3). Furthermore, the scenario 'prediccion_estimacion' assigned to this invented request is incorrect, as 'la felicidad del hogar' is not a valid concept for technical prediction or estimation (B1). While the model correctly identifies the original query as 'entrada_inadmisible', the subsequent flawed decomposition and classification significantly reduce its accuracy. | E11: ¿Qué tan feliz estuvo mi casa ayer con el consumo de energía?
A12: =_xlfn.XLOOKUP(E12,Orden_preguntas!$B:$B,Orden_preguntas!$A:$A) -> 11 | B12: {'1': {'solicitud': 'Consultar consumo energético de la nevera y la lavadora ayer', 'escenario': 'consumo_basico'}} | notas: La solicitud es clara y se ajusta a los criterios del escenario de consumo básico. | C12: 0.3 | D12: The model failed to correctly decompose the input into individual, independent intentions (A1). The input 'Dime el consumo de mi nevera ayer y el consumo de mi lavadora ayer' clearly contains two distinct requests for energy consumption, but the actual output incorrectly combined them into a single, aggregated request, which is a significant shortcoming in semantic quality. | E12: Dime el consumo de mi nevera ayer y el consumo de mi lavadora ayer.
A13: =_xlfn.XLOOKUP(E13,Orden_preguntas!$B:$B,Orden_preguntas!$A:$A) -> 12 | B13: {'1': {'solicitud': '¿Cuánto consumieron el televisor y el computador el sábado pasado?', 'escenario': 'consumo_basico'}, '2': {'solicitud': 'Consulta de valores puntuales de consumo energético históricos para dispositivos específicos en un periodo de tiempo claro.', 'escenario': 'consumo_basico'}} | notas: La solicitud se ajusta a un escenario de consumo básico, que se define como la consulta de valores de consumo energético ya registrados para un dispositivo o zona del hogar en un período de tiempo específico. | C13: 0.2 | D13: The model failed to correctly decompose the input into individual, independent intentions (A1). Instead of separating the requests for 'televisor' and 'computador' as shown in the Expected Output, it kept the original combined query as 'solicitud 1' and then invented a generic description of a request as 'solicitud 2' (A2). This also indicates a failure to infer implicit intentions (A3). While the assigned scenario 'consumo_basico' is correct for the type of query, the fundamental issues in decomposition and invention of information lead to a low score. | E13: ¿Cuánto consumieron el televisor y el computador el sábado pasado?
... A51: =_xlfn.XLOOKUP(E51,Orden_preguntas!$B:$B,Orden_preguntas!$A:$A) -> 50 | B51: {'1': {'solicitud': 'Obtener consumo energético de la nevera ayer', 'escenario': 'consumo_basico'}, '2': {'solicitud': 'Comparar consumo energético de la nevera y la lavadora', 'escenario': 'comparacion_consumos'}, '3': {'solicitud': 'Establecer si el consumo de ambas máquinas permite ahorrar para viajar', 'escenario': 'prediccion_estimacion'}} | notas: Se han identificado dos solicitudes: una para obtener el consumo de la nevera ayer, otra para comparar el consumo de la nevera y la lavadora. La tercera solicitud es ambigua ya que no especifica cómo determinar si el consumo de ambas máquinas permite ahorrar para viajar. | C51: 0.6 | D51: The model correctly decomposes the input into three intentions (A1) and does not invent information (A2). It correctly classifies the first two intentions as 'consumo_basico' and 'comparacion_consumos' (B1). However, it incorrectly classifies the third intention, 'Establecer si el consumo de ambas máquinas permite ahorrar para viajar', as 'prediccion_estimacion' instead of 'entrada_inadmisible' as per the Expected Output (B1 error). Additionally, the 'notas' field contains a minor internal inconsistency by stating 'Se han identificado dos solicitudes' while proceeding to describe three distinct requests (A4). | E51: Dime el consumo de mi nevera ayer, compárala con la lavadora y dime si con eso ya puedo ahorrar para irme de viaje.

Sheet llama31_8b
A1: ID_PREGUNTA | B1: Respuesta_Modelo | C1: Puntaje_Calidad | D1: Razon_del_Juez | E1: Pregunta
A2: =_xlfn.XLOOKUP(E2,Orden_preguntas!$B:$B,Orden_preguntas!$A:$A) -> 1 | B2: {'@1': {'solicitud': '¿Cuánto consumió mi televisor ayer en la noche?', 'escenario': 'consumo_basico', 'descripcion': 'Solicitudes cuya intención principal es consultar valores de consumo energético ya registrados para uno o varios dispositivos, zonas del hogar o el hogar completo, dentro de un intervalo temporal explícito o claramente inferible. La intención es acceder a datos puntuales o históricos sin realizar comparaciones analíticas, análisis de patrones, inferencias ni estimaciones.', 'notas': 'La solicitud menciona una consulta explícita con respecto al consumo energético de un dispositivo específico (televisor) en un período temporal específico (ayer en la noche), lo que coincide con el escenario de consumo básico.'}} | notas: Se identificó el escenario como "consumo_basico" debido a que la solicitud se centra en acceder a datos históricos de consumo energético para un dispositivo específico (televisor) dentro de un intervalo temporal explícito (ayer en la noche). | C2: 1 | D2: The model correctly identified the single intention from the input, '¿Cuánto consumió mi televisor ayer en la noche?', without inventing any information. It accurately classified this intention as 'consumo_basico', which perfectly aligns with the provided description for this scenario, focusing on querying historical consumption for a specific device (televisor) and an explicit time frame (ayer en la noche). The reasoning provided in the 'notas' field is clear, consistent, and directly supports the chosen classification, demonstrating strong internal coherence. | E2: ¿Cuánto consumió mi televisor ayer en la noche?
A3: =_xlfn.XLOOKUP(E3,Orden_preguntas!$B:$B,Orden_preguntas!$A:$A) -> 2 | B3: {'@1': {'solicitud': 'Dime el consumo de mi lavadora el lunes pasado.', 'escenario': 'consumo_basico'}} | notas: La solicitud se categoriza como 'consumo_basico' porque el usuario solicita valores de consumo energético históricos para un dispositivo específico (la lavadora) dentro de un intervalo temporal explícito (el lunes pasado). | C3: 1 | D3: The model correctly decomposes the input 'Dime el consumo de mi lavadora el lunes pasado.' into a single, independent intention without inventing information (A1, A2). The assigned scenario classification 'consumo_basico' is correct according to the expected output (B1). Furthermore, the 'notas' field provides a clear and consistent explanation for this classification, demonstrating strong internal coherence (A4). | E3: Dime el consumo de mi lavadora el lunes pasado.
A4: =_xlfn.XLOOKUP(E4,Orden_preguntas!$B:$B,Orden_preguntas!$A:$A) -> 3 | B4: {'@1': {'solicitud': 'El usuario solicitó conocer el consumo total de la casa durante marzo de 2024.', 'escenario': 'consumo_basico'}} | notas: La solicitud corresponde a buscar valores históricos sin realizar comparaciones o inferencias, por lo que se clasifica bajo el escenario de 'consumo_basico'. | C4: 0.9 | D4: The model correctly decomposed the input '¿Cuál fue el consumo total de la casa durante marzo de 2024?' into a single, independent request, aligning with A1 and A2. The inferred intention, 'El usuario solicitó conocer el consumo total de la casa durante marzo de 2024.', accurately matches the 'Expected Output's interpretation for A3. Furthermore, the 'consumo_basico' scenario was correctly assigned, fulfilling B1, and the 'notas' field provided a clear and coherent explanation for A4. | E4: ¿Cuál fue el consumo total de la casa durante marzo de 2024?
A5: =_xlfn.XLOOKUP(E5,Orden_preguntas!$B:$B,Orden_preguntas!$A:$A) -> 4 | B5: {'@1': {'solicitud': 'Quiero saber cuánta energía gastó mi computador hoy', 'escenario': 'consumo_basico', 'notas': 'La intención principal es consultar valores de consumo energético históricos, lo que se ajusta a el escenario de consumo basico'}} | notas: La solicitud se ajusta al escenario de consumo basico porque solicita información sobre consumo energético en un momento específico (hoy) y no requiere análisis ni comparación. | C5: 1 | D5: The model correctly decomposes the input 'Quiero saber cuánta energía gastó mi computador hoy' into a single request without inventing information (A1, A2). The interpretation of the user's intention in the 'solicitud' field aligns perfectly with the expected output (A3). Furthermore, the model accurately classifies the request under the 'consumo_basico' scenario, matching the expected output (B1). The 'notas' field provides a clear and coherent explanation for this classification (A4). | E5: Quiero saber cuánta energía gastó mi computador hoy.
A6: =_xlfn.XLOOKUP(E6,Orden_preguntas!$B:$B,Orden_preguntas!$A:$A) -> 5 | B6: {'1': {'solicitud': '¿Cuánto consumió el aire acondicionado el fin de semana pasado?', 'escenario': 'consumo_basico', 'notas': 'La solicitud se refiere al consumo histórico del aire acondicionado, lo que corresponde con la intención de consultar valores de consumo energético ya registrados. El escenario "consumo_basico" es adecuado porque el usuario busca acceder a datos puntuales sin realizar comparaciones analíticas.'}} | notas: La solicitud se refiere al consumo histórico del aire acondicionado, lo que corresponde con la intención de consultar valores de consumo energético ya registrados. El escenario "consumo_basico" es adecuado porque el usuario busca acceder a datos puntuales sin realizar comparaciones analíticas. | C6: 1 | D6: The model correctly identified a single intention from the input, accurately classifying it as 'consumo_basico', which aligns perfectly with the Expected Output. The 'notas' field provides clear and consistent reasoning for this classification, demonstrating strong internal coherence and adherence to all evaluation criteria (A1-A4, B1). | E6: ¿Cuánto consumió el aire acondicionado el fin de semana pasado?
A7: =_xlfn.XLOOKUP(E7,Orden_preguntas!$B:$B,Orden_preguntas!$A:$A) -> 6 | B7: {'@1': {'solicitud': 'Consumo del ventilador el día de ayer', 'escenario': 'consumo_basico'}, '@2': {'solicitud': '', 'escenario': 'entrada_inadmisible'}} | notas: La solicitud se categoriza en el escenario 'consumo_basico' porque solicita valores de consumo energético históricos para un dispositivo específico (el ventilador) y menciona un período de tiempo explícito (el día de ayer). La segunda solicitud no está relacionada con consumo energético y por lo tanto se categoriza en el escenario 'entrada_inadmisible'. | C7: 0.3 | D7: The model fails in the decomposition of the input by generating two requests when only one is present in the 'Input'. Specifically, it incorrectly creates an empty request '@2' and assigns it the 'entrada_inadmisible' scenario, which is an invention of information not deducible from the 'Input'. While the first request '@1' correctly interprets the user's intention and assigns the correct 'consumo_basico' scenario, the overall decomposition and the invention of the second, inadmissible request lead to insufficient semantic quality (A1-A4). | E7: Muéstrame el consumo del ventilador el día de ayer.
A8: =_xlfn.XLOOKUP(E8,Orden_preguntas!$B:$B,Orden_preguntas!$A:$A) -> 7 | B8: {'1': {'solicitud': 'El consumo energético de mi horno el 15 de noviembre', 'escenario': 'consumo_basico'}, '2': {'solicitud': 'Consumo energético del horno en noviembre', 'escenario': 'consumo_basico'}} | notas: Se han categorizado las solicitudes como corresponde al escenario de consumo básico ya que se solicitan valores de consumo energético históricos con fechas explícitas. | C8: 0.3 | D8: The model incorrectly decomposes the input by generating two requests when only one specific request was present. The second request, 'Consumo energético del horno en noviembre,' invents information not deducible from the input, which specifically asked for 'el 15 de noviembre.' This demonstrates a failure in criteria A1 and A2, as the model invents information and does not correctly interpret the input's natural language as a single, precise query, leading to insufficient semantic quality. | E8: ¿Cuál fue el consumo energético de mi horno el 15 de noviembre?
A9: =_xlfn.XLOOKUP(E9,Orden_preguntas!$B:$B,Orden_preguntas!$A:$A) -> 8 | B9: {'@1': {'solicitud': 'Se requiere la cantidad de kWh que consumió mi casa durante la semana pasada', 'escenario': 'consumo_basico'}, '@2': {'solicitud': '', 'escenario': ''}} | notas: El sistema clasificó la solicitud como un escenario básico de consumo porque el usuario solicitó valores históricos de consumo energético, específicamente para una semana pasada. Este escenario se ajusta a las características del 'consumo_basico'. | C9: 0.7 | D9: The model correctly interprets the user's intention to query historical energy consumption for the house last week (A3) and accurately assigns the 'consumo_basico' scenario (B1). The 'notas' field is clear and coherent (A4). However, the decomposition is not entirely correct (A1) because the 'Actual Output' includes an unnecessary and empty request ('@2'), which deviates from the 'Expected Output' that correctly identifies only one request. This minor flaw in decomposition prevents a higher score, despite the correct classification of the primary request. | E9: Dime cuántos kWh consumió mi casa la semana pasada.
A10: =_xlfn.XLOOKUP(E10,Orden_preguntas!$B:$B,Orden_preguntas!$A:$A) -> 9 | B10: {'@1': {'solicitud': '¿Cuánto consumió mi nevera durante el mes de enero?', 'escenario': 'consumo_basico', 'notas': 'La solicitud solicita un valor cuantitativo específico del consumo energético histórico de la nevera, dentro de un intervalo temporal explícito (el mes de enero). Se requiere acceso a datos puntuales para responder.'}} | notas: Se seleccionó el escenario de 'consumo_basico' porque la solicitud solicita una consulta sobre valores de consumo energético históricos específicos, dentro de un intervalo temporal explícito (el mes de enero). | C10: 0.9 | D10: The model correctly decomposes the single input request into one independent request (A1) and does not invent any information (A2). The inferred intention in the 'solicitud' field, although using the exact input phrase instead of rephrasing, accurately aligns with the 'Expected Output's interpretation of querying energy consumption for the fridge in January (A3). The assigned scenario 'consumo_basico' is correct and matches the 'Expected Output' (B1). Furthermore, the 'notas' field provides a clear and coherent explanation for the scenario selection, referencing the specific details of the request (A4). | E10: ¿Cuánto consumió mi nevera durante el mes de enero?
A11: =_xlfn.XLOOKUP(E11,Orden_preguntas!$B:$B,Orden_preguntas!$A:$A) -> 10 | B11: {'@1': {'solicitud': '¿Qué tan feliz estuvo mi casa ayer con el consumo de energía?', 'escenario': 'consumo_basico', 'notas': 'La intención principal es acceder a datos puntuales o históricos sin realizar comparaciones analíticas, análisis de patrones, inferencias ni estimaciones.'}} | notas: La solicitud puede ser categorizada como una consulta de consumo básico porque el usuario pregunta sobre la felicidad de su casa en relación con el consumo energético del día anterior, lo cual se ajusta a la descripción del escenario de consumo_basico. | C11: 0.2 | D11: The model incorrectly classifies the input '¿Qué tan feliz estuvo mi casa ayer con el consumo de energía?' as 'consumo_basico' (B1 failure). The input is a metaphorical, non-technical query, which the Expected Output correctly identifies as 'entrada_inadmisible'. Furthermore, the reasoning provided in the 'notas' field is semantically incoherent (A4 failure), attempting to justify the 'consumo_basico' classification by claiming that asking about the 'happiness' of a house 'se ajusta a la descripción del escenario de consumo_basico' (which is for accessing 'datos puntuales o históricos'). This demonstrates a fundamental misunderstanding of the input's meaning and the scenario's definition. | E11: ¿Qué tan feliz estuvo mi casa ayer con el consumo de energía?
A12: =_xlfn.XLOOKUP(E12,Orden_preguntas!$B:$B,Orden_preguntas!$A:$A) -> 11 | B12: {'@1': {'solicitud': 'Consulta del consumo energético histórico de la nevera y la lavadora para ayer.', 'escenario': 'consumo_basico'}, '@2': {'solicitud': 'Consulta del consumo energético histórico de la nevera y la lavadora para ayer.', 'escenario': 'consumo_basico'}} | notas: El usuario solicita valores de consumo energético históricos específicos para dispositivos (nevera y lavadora) durante un período temporal explícito (ayer), por lo que corresponde a escenarios de entrada admitidos por el sistema relacionados con consultas básicas sobre consumo. | C12: 0.2 | D12: The actual output fails to correctly decompose the input into individual, independent intentions (A1). Both decomposed requests, '@1' and '@2', contain the exact same combined 'solicitud' for 'nevera y lavadora', instead of separating them into distinct requests for each appliance as indicated by the input and expected output. This represents a significant shortcoming in the semantic quality of the decomposition, despite the correct scenario classification ('consumo_basico') and the absence of invented information. | E12: Dime el consumo de mi nevera ayer y el consumo de mi lavadora ayer.
A13: =_xlfn.XLOOKUP(E13,Orden_preguntas!$B:$B,Orden_preguntas!$A:$A) -> 12 | B13: {'@1': {'solicitud': '¿Cuánto consumieron el televisor y el computador el sábado pasado?', 'escenario': 'consumo_basico'}} | notas: La solicitud se corresponde con el escenario de consumo básico porque la intención principal es consultar valores de consumo energético históricos para dispositivos específicos (el televisor y el computador) dentro de un intervalo temporal explícito o claramente inferible. | C13: 0.3 | D13: The model failed to correctly decompose the input into all individual, independent intentions (A1). It treated 'el televisor y el computador' as a single request, whereas the expected output correctly identified two distinct requests for each device. While the scenario classification for the combined request was correct, the fundamental failure in decomposition places the response in the lower score range. | E13: ¿Cuánto consumieron el televisor y el computador el sábado pasado?
... A51: =_xlfn.XLOOKUP(E51,Orden_preguntas!$B:$B,Orden_preguntas!$A:$A) -> 50 | B51: {'@1': {'solicitud': 'Dime el consumo de mi nevera ayer', 'escenario': 'consumo_basico'}, '@2': {'solicitud': 'Compara el consumo de la nevera con la lavadora', 'escenario': 'comparacion_consumos'}, '@3': {'solicitud': 'Dime si con eso ya puedo ahorrar para irme de viaje', 'escenario': 'prediccion_estimacion'}} | notas: Para la primera solicitud, se ha seleccionado el escenario de consumo básico porque el usuario solicita información específica sobre el consumo histórico de su nevera. Para la segunda solicitud, se ha elegido comparar consumos debido a que el usuario pide una comparación directa entre dos dispositivos. La tercera solicitud fue asignada al escenario de predicción y estimación porque el usuario pregunta si puede ahorrar dinero para un viaje, lo que implica necesitar hacer alguna proyección o inferencia sobre sus costos futuros. | C51: 0.6 | D51: El modelo descompone correctamente la entrada en tres solicitudes independientes y su interpretación de las intenciones del usuario es adecuada para las solicitudes '@1' y '@2'. Las 'notas' también son claras y coherentes. Sin embargo, el modelo clasifica incorrectamente la tercera solicitud, 'Dime si con eso ya puedo ahorrar para irme de viaje', como 'prediccion_estimacion'. La clasificación correcta, según el 'Expected Output', debería ser 'entrada_inadmisible', lo que indica que el modelo no reconoce los límites de su dominio para esta petición específica. | E51: Dime el consumo de mi nevera ayer, compárala con la lavadora y dime si con eso ya puedo ahorrar para irme de viaje.

Sheet mistral_7b
A1: ID_PREGUNTA | B1: Respuesta_Modelo | C1: Puntaje_Calidad | D1: Razon_del_Juez | E1: Pregunta
A2: =_xlfn.XLOOKUP(E2,Orden_preguntas!$B:$B,Orden_preguntas!$A:$A) -> 1 | B2: {'@1': {'solicitud': 'Consulta histórica del consumo diario de un dispositivo específico (televisor)', 'escenario': 'consumo_basico'}} | notas: La consulta se relaciona explícitamente con el consumo energético histórico del hogar, más precisamente de un dispositivo específico (televisor) y en un periodo determinado (ayer). El usuario no menciona comparaciones analíticas, análisis de patrones ni inferencias, lo que coincide con el escenario 'consumo_basico'. | C2: 0.9 | D2: The model correctly decomposes the input into a single request and accurately interprets the user's intention to query historical consumption for a specific device (televisor) during a defined period ('ayer en la noche'). The assigned scenario 'consumo_basico' aligns perfectly with the nature of the request, and the 'notas' provide a clear and coherent justification for both the request interpretation and the scenario classification. The 'solicitud' in the actual output uses 'consumo diario' which is a slight generalization compared to 'noche de ayer' in the expected output, but it doesn't invent information or misinterpret the core intent, hence a high score. | E2: ¿Cuánto consumió mi televisor ayer en la noche?
A3: =_xlfn.XLOOKUP(E3,Orden_preguntas!$B:$B,Orden_preguntas!$A:$A) -> 2 | B3: {'@1': {'solicitud': 'El usuario solicita un valor de consumo energético histórico específico para su lavadora el lunes pasado.', 'escenario': 'consumo_basico'}} | notas: La consulta incluye un periodo de tiempo explícito y claramente inferible, y la respuesta esperada es un valor cuantitativo único. | C3: 1 | D3: The model correctly decomposes the input into a single intention (A1) without inventing information (A2). It accurately classifies the request as 'consumo_basico' (B1), matching the Expected Output. The 'notas' field provides a clear and consistent explanation for the identified request and its classification, demonstrating strong internal coherence (A4). The model correctly infers the explicit intention for historical consumption (A3). | E3: Dime el consumo de mi lavadora el lunes pasado.
A4: =_xlfn.XLOOKUP(E4,Orden_preguntas!$B:$B,Orden_preguntas!$A:$A) -> 3 | B4: {'@1': {'solicitud': 'Consultar consumo total del hogar durante marzo de 2024', 'escenario': 'consumo_basico'}} | notas: La solicitud especifica un periodo de tiempo explícito (marzo de 2024) y busca valores cuantitativos, por lo que se categoriza como un escenario de consumo básico. | C4: 1 | D4: The model correctly decomposes the single input request into an individual request (A1) without inventing any information (A2). The inferred intention in the 'solicitud' field, 'Consultar consumo total del hogar durante marzo de 2024', accurately interprets the input '¿Cuál fue el consumo total de la casa durante marzo de 2024?', aligning closely with the expected output's interpretation (A3). The assigned scenario 'consumo_basico' is correct and matches the expected output (B1). Furthermore, the 'notas' field provides a clear and coherent explanation for the classification, stating that the request specifies an explicit time period and seeks quantitative values (A4). | E4: ¿Cuál fue el consumo total de la casa durante marzo de 2024?
A5: =_xlfn.XLOOKUP(E5,Orden_preguntas!$B:$B,Orden_preguntas!$A:$A) -> 4 | B5: {'@1': {'solicitud': 'Solicitud de consulta del consumo energético diario del computador', 'escenario': 'consumo_basico'}} | notas: El usuario ha solicitado información puntual sobre el consumo diario de su computador, lo que corresponde al escenario de entrada 'consumo_basico'. No hay necesidad de realizar comparaciones analíticas ni estimaciones. | C5: 1 | D5: The model correctly decomposed the input into a single request, accurately reflecting the user's intention to query daily computer energy consumption (A1, A2, A3). The 'solicitud' field, 'Solicitud de consulta del consumo energético diario del computador', precisely matches the intent of 'Quiero saber cuánta energía gastó mi computador hoy'. Furthermore, the model correctly classified this request under the 'consumo_basico' scenario, aligning perfectly with the Expected Output (B1). The 'notas' field provides a clear and coherent explanation for this classification (A4). | E5: Quiero saber cuánta energía gastó mi computador hoy.
A6: =_xlfn.XLOOKUP(E6,Orden_preguntas!$B:$B,Orden_preguntas!$A:$A) -> 5 | B6: {'@1': {'solicitud': 'Consulta de consumo energético histórico para un dispositivo específico', 'escenario': 'consumo_basico'}} | notas: La solicitud del usuario busca un valor cuantitativo único referente al consumo del aire acondicionado durante el fin de semana pasado, lo que se encuentra en la categoría 'consumo_basico'. No hay necesidad de realizar comparaciones analíticas ni inferencias. | C6: 1 | D6: El modelo descompone correctamente la intención del usuario '¿Cuánto consumió el aire acondicionado el fin de semana pasado?' en 'Consulta de consumo energético histórico para un dispositivo específico' (A1, A2). La clasificación del escenario como 'consumo_basico' es correcta y coincide con el Expected Output (B1). Además, la explicación en el campo 'notas' es clara y coherente con la solicitud identificada y su clasificación, justificando por qué se categoriza como 'consumo_basico' (A4). No se inventa información ni se omiten intenciones implícitas relevantes (A3). | E6: ¿Cuánto consumió el aire acondicionado el fin de semana pasado?
A7: =_xlfn.XLOOKUP(E7,Orden_preguntas!$B:$B,Orden_preguntas!$A:$A) -> 6 | B7: {'@1': {'solicitud': 'Consultar consumo histórico de un dispositivo (ventilador) para un día específico (el día de ayer)', 'escenario': 'consumo_basico'}} | notas: La consulta es explícita y claramente relacionada con el consumo energético del hogar, solicita datos históricos de un dispositivo específico para un día especificado. El sistema interpreta esta solicitud como una consulta de tipo 'consumo_basico'. | C7: 1 | D7: The model accurately decomposes the input 'Muéstrame el consumo del ventilador el día de ayer' into the correct intention, 'Consultar consumo histórico de un dispositivo (ventilador) para un día específico (el día de ayer)', aligning with A1 and A2. The scenario 'consumo_basico' is correctly assigned (B1), and the 'notas' provide clear, coherent reasoning (A4), demonstrating full compliance with the evaluation criteria. | E7: Muéstrame el consumo del ventilador el día de ayer.
A8: =_xlfn.XLOOKUP(E8,Orden_preguntas!$B:$B,Orden_preguntas!$A:$A) -> 7 | B8: {'@1': {'solicitud': 'Consulta de consumo energético histórico para un dispositivo específico', 'escenario': 'consumo_basico'}} | notas: La consulta es específica sobre el horno y el día concreto del 15 de noviembre, lo que hace claro que se trata de una solicitud para acceder a datos puntuales sin realizar comparaciones ni análisis. | C8: 0.9 | D8: El modelo descompone correctamente la solicitud del usuario en una única intención y no inventa información. La clasificación del escenario como 'consumo_basico' es correcta y coincide con el Expected Output. La nota proporcionada es coherente y justifica adecuadamente la clasificación, mencionando la especificidad del horno y la fecha del 15 de noviembre. La 'solicitud' identificada en el Actual Output es funcionalmente correcta, aunque ligeramente menos específica que la del Expected Output, lo cual no afecta la clasificación ni la comprensión general de la intención. | E8: ¿Cuál fue el consumo energético de mi horno el 15 de noviembre?
A9: =_xlfn.XLOOKUP(E9,Orden_preguntas!$B:$B,Orden_preguntas!$A:$A) -> 8 | B9: {'@1': {'solicitud': 'Consultar el consumo energético histórico de la casa durante la semana pasada', 'escenario': 'consumo_basico'}} | notas: La consulta es explícita en su intención de obtener información de consumo energético, se menciona un período de tiempo claramente inferible (la semana pasada) y el resultado esperado es un valor único. | C9: 0.9 | D9: The model correctly decomposed the single request from the input 'Dime cuántos kWh consumió mi casa la semana pasada' into an independent request without inventing information. The inferred intention 'Consultar el consumo energético histórico de la casa durante la semana pasada' accurately reflects the input and closely aligns with the expected output's interpretation. The assigned scenario 'consumo_basico' is correct and matches the expected output. The 'notas' field provides a clear and coherent explanation of the request, demonstrating strong semantic understanding. | E9: Dime cuántos kWh consumió mi casa la semana pasada.
